<?xml version='1.0'?>
<robot name="dd_robot">

  <!-- Base Link -->
  <link name="base_link">
    <visual>
      <origin xyz="0 0 0" rpy="0 0 0" />
      <geometry>
        <box size="0.6096 0.4191 0.07"/>
      </geometry>
      <material name="blue">
        <color rgba="0 0.5 1 1"/>
      </material>
    </visual>
    <!-- Base collision, mass and inertia -->
    <collision>
      <origin xyz="0 0 0" rpy="0 0 0" />
      <geometry>
        <box size="0.6096 0.4191 0.07"/>
      </geometry>
    </collision>
    <inertial>
      <mass value="5"/>
      <inertia ixx="0.13" ixy="0.0" ixz="0.0" iyy="0.21" iyz="0.0" izz="0.13"/>
    </inertial>
  </link>

  <!-- base footprint -->

  <link name="base_footprint"></link>

  <!-- base_footprint joint -->

  <joint name="footprint_joint">
    <parent link="base_footprint"/>
    <child link="base_link"/>
    <origin xyz="0 0 0.0762"  rpy="0 0 0" />
    <axis xyz="0 0 0" />

  </joint>

  <!-- Right Wheel -->
  <link name="right_wheel">
    <visual>
      <origin xyz="0 0 0"  rpy="1.570795 0 0" />
      <geometry>
        <cylinder radius="0.0762" length="0.04318"/>
      </geometry>
      <material name="darkgray">
        <color rgba=".2 .2 .2 1"/>
      </material>
    </visual>
    <!-- Right Wheel collision, mass and inertia -->
    <collision>
      <origin xyz="0 0 0"  rpy="1.570795 0 0" />
      <geometry>
        <cylinder radius="0.0762" length="0.04318"/>
      </geometry>
    </collision>
    <inertial>
      <mass value="0.5"/>
      <inertia ixx="0.01" ixy="0.0" ixz="0.0" iyy="0.005" iyz="0.0" izz="0.005"/>
    </inertial>

  </link>

  <!-- Right Wheel joint -->
  <joint name="joint_right_wheel" type="continuous">
    <parent link="base_link"/>
    <child link="right_wheel"/>
    <origin xyz="0.2 0.24 0"  rpy="0 0 0" /> 
    <axis xyz="0 1 0" />
  </joint>

  <!-- Left Wheel -->
  <link name="left_wheel">
    <visual>
      <origin xyz="0 0 0"  rpy="1.570795 0 0" />
      <geometry>
        <cylinder radius="0.0762" length="0.04318"/>
      </geometry>
      <material name="darkgray">
        <color rgba=".2 .2 .2 1"/>
      </material>
    </visual>
    <!-- Left Wheel collision, mass and inertia -->
    <collision>
      <origin xyz="0 0 0" rpy="1.570795 0 0" />
      <geometry>
        <cylinder radius="0.0762" length="0.04318"/>
      </geometry>
    </collision>
    <inertial>
      <mass value="0.5"/>
      <inertia ixx="0.01" ixy="0.0" ixz="0.0" iyy="0.005" iyz="0.0" izz="0.005"/>
    </inertial>
  </link>

  <!-- Left Wheel joint -->
  <joint name="joint_left_wheel" type="continuous">
    <parent link="base_link"/>
    <child link="left_wheel"/>
    <origin xyz="0.2 -0.24 0"  rpy="0 0 0" /> 
    <axis xyz="0 1 0" />
  </joint>

  <link name="caster">
    <inertial>
            <mass value="1" />
            <inertia ixx="0.1316" ixy="0.0" ixz="0" iyy="0.1316" iyz="0" izz="0.01125" />
    </inertial>
    <visual>    
      <geometry>
        <sphere radius="0.0381" />
      </geometry>
      <material name="white" />
        <color rgba="1 1 1 1"/>
    </visual>
  </link>
  <joint name="caster_joint" type="continuous">
    <origin xyz="-0.25 0.0 -0.07" rpy="1.57 0.0 0.0"/>
    <parent link="base_link"/>
    <child link="caster"/>
  </joint>

  <link name="laser">
    <inertial>
            <mass value="1.0" />
            <inertia ixx="0.004375" ixy="0.0" ixz="0" iyy="0.004375" iyz="0" izz="0.005" />
    </inertial>
    <visual>	 
      <geometry>
        <cylinder radius="0.05" length="0.05"/>
      </geometry>
      <material name="grass">
        <color rgba="0.3607843137254902 0.6745098039215687 0.17647058823529413 1.0" />
      </material>
    </visual>
  </link>
  <joint name="laser_joint" type="fixed">
    <origin xyz="0.225 0 0.07" rpy="0 0 3.1416"/>
    <parent link="base_link"/>
    <child link="laser"/>
    <axis xyz="0.0 0.0 1.0"/>
  </joint>

</robot>